2024-10-16T22:15:51.914669 - ERROR - Erreur lors de la récupération des données pour BOTZ (Tentative 1/3): 'dict' object has no attribute 'to_dict'
2024-10-16T22:15:51.926264 - ERROR - Erreur lors de la récupération des données pour XLK (Tentative 1/3): 'dict' object has no attribute 'to_dict'
2024-10-16T22:15:52.388507 - ERROR - Erreur lors de la récupération des données pour VGT (Tentative 1/3): 'dict' object has no attribute 'to_dict'
2024-10-16T22:15:52.390759 - ERROR - Erreur lors de la récupération des données pour IXN (Tentative 1/3): 'dict' object has no attribute 'to_dict'
2024-10-16T22:15:52.415591 - ERROR - Erreur lors de la récupération des données pour QQQ (Tentative 1/3): 'dict' object has no attribute 'to_dict'
2024-10-16T22:15:59.688993 - ERROR - Erreur lors de la récupération des données pour BOTZ (Tentative 2/3): 'dict' object has no attribute 'to_dict'
2024-10-16T22:16:00.155532 - ERROR - Erreur lors de la récupération des données pour XLK (Tentative 2/3): 'dict' object has no attribute 'to_dict'
2024-10-16T22:16:00.641368 - ERROR - Erreur lors de la récupération des données pour QQQ (Tentative 2/3): 'dict' object has no attribute 'to_dict'
2024-10-16T22:16:00.642553 - ERROR - Erreur lors de la récupération des données pour VGT (Tentative 2/3): 'dict' object has no attribute 'to_dict'
2024-10-16T22:16:01.251034 - ERROR - Erreur lors de la récupération des données pour IXN (Tentative 2/3): 'dict' object has no attribute 'to_dict'
2024-10-16T22:16:08.608602 - ERROR - Erreur lors de la récupération des données pour XLK (Tentative 3/3): 'dict' object has no attribute 'to_dict'
2024-10-16T22:16:08.611955 - ERROR - Erreur lors de la récupération des données pour BOTZ (Tentative 3/3): 'dict' object has no attribute 'to_dict'
2024-10-16T22:16:09.106099 - ERROR - Erreur lors de la récupération des données pour VGT (Tentative 3/3): 'dict' object has no attribute 'to_dict'
2024-10-16T22:16:09.106531 - ERROR - Erreur lors de la récupération des données pour QQQ (Tentative 3/3): 'dict' object has no attribute 'to_dict'
2024-10-16T22:16:09.645701 - ERROR - Erreur lors de la récupération des données pour IXN (Tentative 3/3): 'dict' object has no attribute 'to_dict'
